ERROR:load_data.py:no such table: film_work
Traceback (most recent call last):
  File "load_data.py", line 136, in main
    movies_data: Dict[str:List[dataclass]] = sqlite_loader.load_movies()
  File "load_data.py", line 62, in load_movies
    movies_data[table_name] = self._load_table(table_name)
  File "load_data.py", line 36, in _load_table
    self.cursor.execute(f'SELECT * FROM {table_name}')
sqlite3.OperationalError: no such table: film_work
ERROR:load_data.py:no such table: film_work
Traceback (most recent call last):
  File "load_data.py", line 136, in main
    movies_data: Dict[str:List[dataclass]] = sqlite_loader.load_movies()
  File "load_data.py", line 62, in load_movies
    movies_data[table_name] = self._load_table(table_name)
  File "load_data.py", line 36, in _load_table
    self.cursor.execute(f'SELECT * FROM {table_name}')
sqlite3.OperationalError: no such table: film_work
INFO:load_data.py:Data loaded from table: film_work, 999 rows
INFO:load_data.py:Data loaded from table: genre, 26 rows
INFO:load_data.py:Data loaded from table: person, 4166 rows
INFO:load_data.py:Data loaded from table: genre_film_work, 2231 rows
INFO:load_data.py:Data loaded from table: person_film_work, 5783 rows
INFO:load_data.py:All tables were loaded from sqlite
ERROR:load_data.py:ERROR:  relation "content.film_work" does not exist
LINE 1: INSERT INTO content.film_work (title, description, id, creat...
                    ^
Traceback (most recent call last):
  File "load_data.py", line 149, in main
    postgres_saver.save_all_data(data=movies_data,
  File "load_data.py", line 101, in save_all_data
    self._save_data_to_table(
  File "load_data.py", line 88, in _save_data_to_table
    execute_values(
  File "/_MYF/1_pr/venv/lib/python3.8/site-packages/psycopg2/extras.py", line 1299, in execute_values
    cur.execute(b''.join(parts))
  File "/_MYF/1_pr/venv/lib/python3.8/site-packages/psycopg2/extras.py", line 146, in execute
    return super().execute(query, vars)
psycopg2.errors.UndefinedTable: relation "content.film_work" does not exist
LINE 1: INSERT INTO content.film_work (title, description, id, creat...
                    ^

INFO:load_data.py:All tasks have worked correctly
INFO:load_data.py:Data loaded from table: film_work, 999 rows
INFO:load_data.py:Data loaded from table: genre, 26 rows
INFO:load_data.py:Data loaded from table: person, 4166 rows
INFO:load_data.py:Data loaded from table: genre_film_work, 2231 rows
INFO:load_data.py:Data loaded from table: person_film_work, 5783 rows
INFO:load_data.py:All tables were loaded from sqlite
ERROR:load_data.py:ERROR:  relation "content.film_work" does not exist
LINE 1: INSERT INTO content.film_work (title, description, id, creat...
                    ^
Traceback (most recent call last):
  File "load_data.py", line 149, in main
    postgres_saver.save_all_data(data=movies_data,
  File "load_data.py", line 101, in save_all_data
    self._save_data_to_table(
  File "load_data.py", line 88, in _save_data_to_table
    execute_values(
  File "/_MYF/1_pr/venv/lib/python3.8/site-packages/psycopg2/extras.py", line 1299, in execute_values
    cur.execute(b''.join(parts))
  File "/_MYF/1_pr/venv/lib/python3.8/site-packages/psycopg2/extras.py", line 146, in execute
    return super().execute(query, vars)
psycopg2.errors.UndefinedTable: relation "content.film_work" does not exist
LINE 1: INSERT INTO content.film_work (title, description, id, creat...
                    ^

INFO:load_data.py:All tasks have worked correctly
INFO:load_data.py:Data loaded from table: film_work, 999 rows
INFO:load_data.py:Data loaded from table: genre, 26 rows
INFO:load_data.py:Data loaded from table: person, 4166 rows
INFO:load_data.py:Data loaded from table: genre_film_work, 2231 rows
INFO:load_data.py:Data loaded from table: person_film_work, 5783 rows
INFO:load_data.py:All tables were loaded from sqlite
INFO:load_data.py:Uploaded 999 rows for table:film_work
INFO:load_data.py:Uploaded 26 rows for table:genre
INFO:load_data.py:Uploaded 4166 rows for table:person
INFO:load_data.py:Uploaded 2231 rows for table:genre_film_work
INFO:load_data.py:Uploaded 5783 rows for table:person_film_work
INFO:load_data.py:All tasks have worked correctly
